Workbook

Sheet 1.承租人-合并源数据
A1: 序号 | B1: 报表分类 | C1: 标准会计科目 | D1: 2022年 | E1: 2023年 | F1: 2024年 | G1: 最新一期
A2: 1 | B2: 资产负债表 | C2: 流动资产合计 | D2: =SUM(D3,D5,D6,D7,D8,D9,D10,D11,D12,D13,D14,D15,D16,D17,D18,D19,D20,D21,D22) | E2: =SUM(E3,E5,E6,E7,E8,E9,E10,E11,E12,E13,E14,E15,E16,E17,E18,E19,E20,E21,E22) | F2: =SUM(F3,F5,F6,F7,F8,F9,F10,F11,F12,F13,F14,F15,F16,F17,F18,F19,F20,F21,F22) | G2: =SUM(G3,G5,G6,G7,G8,G9,G10,G11,G12,G13,G14,G15,G16,G17,G18,G19,G20,G21,G22)
A3: 2 | C3: 货币资金
A4: 3 | C4: 其中：受限货币资金
A5: 4 | C5: 结算备付金
A6: 5 | C6: 拆出资金
A7: 6 | C7: 交易性金融资产 / 短期投资
A8: 7 | C8: 衍生金融资产
A9: 8 | C9: 应收票据
A10: 9 | C10: 应收账款
A11: 10 | C11: 应收款项融资
A12: 11 | C12: 预付款项
A13: 12 | C13: 应收保费 / 应收分保账款
A14: 13 | C14: 应收利息
... A22: 21 | C22: 其他流动资产
A23: 22 | C23: 非流动资产合计 | D23: =SUM(D24,D25,D26,D27,D28,D29,D30,D31,D32,D34,D35,D36,D37,D38,D39,D40,D41,D42) | E23: =SUM(E24,E25,E26,E27,E28,E29,E30,E31,E32,E34,E35,E36,E37,E38,E39,E40,E41,E42) | F23: =SUM(F24,F25,F26,F27,F28,F29,F30,F31,F32,F34,F35,F36,F37,F38,F39,F40,F41,F42) | G23: =SUM(G24,G25,G26,G27,G28,G29,G30,G31,G32,G34,G35,G36,G37,G38,G39,G40,G41,G42)
A24: 23 | C24: 发放贷款和垫款
A25: 24 | C25: 债权投资 / 持有至到期投资
A26: 25 | C26: 其他债权投资 / 可供出售金融资产
A27: 26 | C27: 长期应收款
A28: 27 | C28: 长期股权投资
A29: 28 | C29: 其他权益工具投资
A30: 29 | C30: 其他非流动金融资产
A31: 30 | C31: 投资性房地产
A32: 31 | C32: 固定资产
A33: 32 | C33: 其中：固定资产清理
A34: 33 | C34: 在建工程
A35: 34 | C35: 生产性生物资产 / 油气资产
... A42: 41 | C42: 其他非流动资产
A43: 42 | C43: 资产总计 | D43: =D2+D23 | E43: =E2+E23 | F43: =F2+F23 | G43: =G2+G23
A44: 43 | C44: 流动负债合计 | D44: =SUM(D45,D46,D47,D48,D49,D50,D51,D52,D53,D54,D55,D56,D57,D60,D61,D62) | E44: =SUM(E45,E46,E47,E48,E49,E50,E51,E52,E53,E54,E55,E56,E57,E60,E61,E62) | F44: =SUM(F45,F46,F47,F48,F49,F50,F51,F52,F53,F54,F55,F56,F57,F60,F61,F62) | G44: =SUM(G45,G46,G47,G48,G49,G50,G51,G52,G53,G54,G55,G56,G57,G60,G61,G62)
A45: 44 | C45: 短期借款
A46: 45 | C46: 向中央银行借款
A47: 46 | C47: 拆入资金 / 吸收存款及同业存放
A48: 47 | C48: 交易性金融负债
A49: 48 | C49: 衍生金融负债
A50: 49 | C50: 应付票据
A51: 50 | C51: 应付账款
A52: 51 | C52: 预收款项
A53: 52 | C53: 合同负债
...

Sheet 2.承租人-本部源数据
A1: 序号 | B1: 报表分类 | C1: 标准会计科目 | D1: 2022年 | E1: 2023年 | F1: 2024年 | G1: 最新一期
A2: 1 | B2: 资产负债表 | C2: 流动资产合计 | D2: =SUM(D3,D5,D6,D7,D8,D9,D10,D11,D12,D13,D14,D15,D16,D17,D18,D19,D20,D21,D22) | E2: =SUM(E3,E5,E6,E7,E8,E9,E10,E11,E12,E13,E14,E15,E16,E17,E18,E19,E20,E21,E22) | F2: =SUM(F3,F5,F6,F7,F8,F9,F10,F11,F12,F13,F14,F15,F16,F17,F18,F19,F20,F21,F22) | G2: =SUM(G3,G5,G6,G7,G8,G9,G10,G11,G12,G13,G14,G15,G16,G17,G18,G19,G20,G21,G22)
A3: 2 | C3: 货币资金
A4: 3 | C4: 其中：受限货币资金
A5: 4 | C5: 结算备付金
A6: 5 | C6: 拆出资金
A7: 6 | C7: 交易性金融资产 / 短期投资
A8: 7 | C8: 衍生金融资产
A9: 8 | C9: 应收票据
A10: 9 | C10: 应收账款
A11: 10 | C11: 应收款项融资
A12: 11 | C12: 预付款项
A13: 12 | C13: 应收保费 / 应收分保账款
A14: 13 | C14: 应收利息
... A22: 21 | C22: 其他流动资产
A23: 22 | C23: 非流动资产合计 | D23: =SUM(D24,D25,D26,D27,D28,D29,D30,D31,D32,D34,D35,D36,D37,D38,D39,D40,D41,D42) | E23: =SUM(E24,E25,E26,E27,E28,E29,E30,E31,E32,E34,E35,E36,E37,E38,E39,E40,E41,E42) | F23: =SUM(F24,F25,F26,F27,F28,F29,F30,F31,F32,F34,F35,F36,F37,F38,F39,F40,F41,F42) | G23: =SUM(G24,G25,G26,G27,G28,G29,G30,G31,G32,G34,G35,G36,G37,G38,G39,G40,G41,G42)
A24: 23 | C24: 发放贷款和垫款
A25: 24 | C25: 债权投资 / 持有至到期投资
A26: 25 | C26: 其他债权投资 / 可供出售金融资产
A27: 26 | C27: 长期应收款
A28: 27 | C28: 长期股权投资
A29: 28 | C29: 其他权益工具投资
A30: 29 | C30: 其他非流动金融资产
A31: 30 | C31: 投资性房地产
A32: 31 | C32: 固定资产
A33: 32 | C33: 其中：固定资产清理
A34: 33 | C34: 在建工程
A35: 34 | C35: 生产性生物资产 / 油气资产
... A42: 41 | C42: 其他非流动资产
A43: 42 | C43: 资产总计 | D43: =D2+D23 | E43: =E2+E23 | F43: =F2+F23 | G43: =G2+G23
A44: 43 | C44: 流动负债合计 | D44: =SUM(D45,D46,D47,D48,D49,D50,D51,D52,D53,D54,D55,D56,D57,D60,D61,D62) | E44: =SUM(E45,E46,E47,E48,E49,E50,E51,E52,E53,E54,E55,E56,E57,E60,E61,E62) | F44: =SUM(F45,F46,F47,F48,F49,F50,F51,F52,F53,F54,F55,F56,F57,F60,F61,F62) | G44: =SUM(G45,G46,G47,G48,G49,G50,G51,G52,G53,G54,G55,G56,G57,G60,G61,G62)
A45: 44 | C45: 短期借款
A46: 45 | C46: 向中央银行借款
A47: 46 | C47: 拆入资金 / 吸收存款及同业存放
A48: 47 | C48: 交易性金融负债
A49: 48 | C49: 衍生金融负债
A50: 49 | C50: 应付票据
A51: 50 | C51: 应付账款
A52: 51 | C52: 预收款项
A53: 52 | C53: 合同负债
...

Sheet 3.承租人-财务分析
A1: 分析板块 | B1: 财务分析科目 | C1: 合并口径 (单位:万元) | G1: 本部口径 (单位:万元)
C2: 2022年 | D2: 2023年 | E2: 2024年 | F2: 最新一期 | G2: 2022年 | H2: 2023年 | I2: 2024年 | J2: 最新一期
A3: 资产 | B3: 总资产 | C3: ='1.承租人-合并源数据'!D43/10000 | D3: ='1.承租人-合并源数据'!E43/10000 | E3: ='1.承租人-合并源数据'!F43/10000 | F3: ='1.承租人-合并源数据'!G43/10000 | G3: ='2.承租人-本部源数据'!D43/10000 | H3: ='2.承租人-本部源数据'!E43/10000 | I3: ='2.承租人-本部源数据'!F43/10000 | J3: ='2.承租人-本部源数据'!G43/10000
B4: 流动资产 | C4: ='1.承租人-合并源数据'!D2/10000 | D4: ='1.承租人-合并源数据'!E2/10000 | E4: ='1.承租人-合并源数据'!F2/10000 | F4: ='1.承租人-合并源数据'!G2/10000 | G4: ='2.承租人-本部源数据'!D2/10000 | H4: ='2.承租人-本部源数据'!E2/10000 | I4: ='2.承租人-本部源数据'!F2/10000 | J4: ='2.承租人-本部源数据'!G2/10000
B5: 货币资金 | C5: ='1.承租人-合并源数据'!D3/10000 | D5: ='1.承租人-合并源数据'!E3/10000 | E5: ='1.承租人-合并源数据'!F3/10000 | F5: ='1.承租人-合并源数据'!G3/10000 | G5: ='2.承租人-本部源数据'!D3/10000 | H5: ='2.承租人-本部源数据'!E3/10000 | I5: ='2.承租人-本部源数据'!F3/10000 | J5: ='2.承租人-本部源数据'!G3/10000
B6: 应收帐款 | C6: ='1.承租人-合并源数据'!D10/10000 | D6: ='1.承租人-合并源数据'!E10/10000 | E6: ='1.承租人-合并源数据'!F10/10000 | F6: ='1.承租人-合并源数据'!G10/10000 | G6: ='2.承租人-本部源数据'!D10/10000 | H6: ='2.承租人-本部源数据'!E10/10000 | I6: ='2.承租人-本部源数据'!F10/10000 | J6: ='2.承租人-本部源数据'!G10/10000
B7: 其他应收款 | C7: ='1.承租人-合并源数据'!D16/10000 | D7: ='1.承租人-合并源数据'!E16/10000 | E7: ='1.承租人-合并源数据'!F16/10000 | F7: ='1.承租人-合并源数据'!G16/10000 | G7: ='2.承租人-本部源数据'!D16/10000 | H7: ='2.承租人-本部源数据'!E16/10000 | I7: ='2.承租人-本部源数据'!F16/10000 | J7: ='2.承租人-本部源数据'!G16/10000
B8: 预付帐款 | C8: ='1.承租人-合并源数据'!D12/10000 | D8: ='1.承租人-合并源数据'!E12/10000 | E8: ='1.承租人-合并源数据'!F12/10000 | F8: ='1.承租人-合并源数据'!G12/10000 | G8: ='2.承租人-本部源数据'!D12/10000 | H8: ='2.承租人-本部源数据'!E12/10000 | I8: ='2.承租人-本部源数据'!F12/10000 | J8: ='2.承租人-本部源数据'!G12/10000
B9: 存货 | C9: ='1.承租人-合并源数据'!D18/10000 | D9: ='1.承租人-合并源数据'!E18/10000 | E9: ='1.承租人-合并源数据'!F18/10000 | F9: ='1.承租人-合并源数据'!G18/10000 | G9: ='2.承租人-本部源数据'!D18/10000 | H9: ='2.承租人-本部源数据'!E18/10000 | I9: ='2.承租人-本部源数据'!F18/10000 | J9: ='2.承租人-本部源数据'!G18/10000
B10: 其他流动资产 | C10: ='1.承租人-合并源数据'!D22/10000 | D10: ='1.承租人-合并源数据'!E22/10000 | E10: ='1.承租人-合并源数据'!F22/10000 | F10: ='1.承租人-合并源数据'!G22/10000 | G10: ='2.承租人-本部源数据'!D22/10000 | H10: ='2.承租人-本部源数据'!E22/10000 | I10: ='2.承租人-本部源数据'!F22/10000 | J10: ='2.承租人-本部源数据'!G22/10000
B11: 持有至到期投资 | C11: ='1.承租人-合并源数据'!D25/10000 | D11: ='1.承租人-合并源数据'!E25/10000 | E11: ='1.承租人-合并源数据'!F25/10000 | F11: ='1.承租人-合并源数据'!G25/10000 | G11: ='2.承租人-本部源数据'!D25/10000 | H11: ='2.承租人-本部源数据'!E25/10000 | I11: ='2.承租人-本部源数据'!F25/10000 | J11: ='2.承租人-本部源数据'!G25/10000
B12: 长期股权投资 | C12: ='1.承租人-合并源数据'!D28/10000 | D12: ='1.承租人-合并源数据'!E28/10000 | E12: ='1.承租人-合并源数据'!F28/10000 | F12: ='1.承租人-合并源数据'!G28/10000 | G12: ='2.承租人-本部源数据'!D28/10000 | H12: ='2.承租人-本部源数据'!E28/10000 | I12: ='2.承租人-本部源数据'!F28/10000 | J12: ='2.承租人-本部源数据'!G28/10000
B13: 投资性房地产 | C13: ='1.承租人-合并源数据'!D31/10000 | D13: ='1.承租人-合并源数据'!E31/10000 | E13: ='1.承租人-合并源数据'!F31/10000 | F13: ='1.承租人-合并源数据'!G31/10000 | G13: ='2.承租人-本部源数据'!D31/10000 | H13: ='2.承租人-本部源数据'!E31/10000 | I13: ='2.承租人-本部源数据'!F31/10000 | J13: ='2.承租人-本部源数据'!G31/10000
B14: 固定资产 | C14: ='1.承租人-合并源数据'!D32/10000 | D14: ='1.承租人-合并源数据'!E32/10000 | E14: ='1.承租人-合并源数据'!F32/10000 | F14: ='1.承租人-合并源数据'!G32/10000 | G14: ='2.承租人-本部源数据'!D32/10000 | H14: ='2.承租人-本部源数据'!E32/10000 | I14: ='2.承租人-本部源数据'!F32/10000 | J14: ='2.承租人-本部源数据'!G32/10000
B15: 其中：本期新增折旧
B16: 在建工程 | C16: ='1.承租人-合并源数据'!D34/10000 | D16: ='1.承租人-合并源数据'!E34/10000 | E16: ='1.承租人-合并源数据'!F34/10000 | F16: ='1.承租人-合并源数据'!G34/10000 | G16: ='2.承租人-本部源数据'!D34/10000 | H16: ='2.承租人-本部源数据'!E34/10000 | I16: ='2.承租人-本部源数据'!F34/10000 | J16: ='2.承租人-本部源数据'!G34/10000
B17: 无形资产 | C17: ='1.承租人-合并源数据'!D37/10000 | D17: ='1.承租人-合并源数据'!E37/10000 | E17: ='1.承租人-合并源数据'!F37/10000 | F17: ='1.承租人-合并源数据'!G37/10000 | G17: ='2.承租人-本部源数据'!D37/10000 | H17: ='2.承租人-本部源数据'!E37/10000 | I17: ='2.承租人-本部源数据'!F37/10000 | J17: ='2.承租人-本部源数据'!G37/10000
B18: 其中：本期新增摊销
B19: 长期待摊费用 | C19: ='1.承租人-合并源数据'!D40/10000 | D19: ='1.承租人-合并源数据'!E40/10000 | E19: ='1.承租人-合并源数据'!F40/10000 | F19: ='1.承租人-合并源数据'!G40/10000 | G19: ='2.承租人-本部源数据'!D40/10000 | H19: ='2.承租人-本部源数据'!E40/10000 | I19: ='2.承租人-本部源数据'!F40/10000 | J19: ='2.承租人-本部源数据'!G40/10000
B20: 其中：本期新增摊销(长待)
B21: 递延所得税资产 | C21: ='1.承租人-合并源数据'!D41/10000 | D21: ='1.承租人-合并源数据'!E41/10000 | E21: ='1.承租人-合并源数据'!F41/10000 | F21: ='1.承租人-合并源数据'!G41/10000 | G21: ='2.承租人-本部源数据'!D41/10000 | H21: ='2.承租人-本部源数据'!E41/10000 | I21: ='2.承租人-本部源数据'!F41/10000 | J21: ='2.承租人-本部源数据'!G41/10000
B22: 其他非流动资产 | C22: ='1.承租人-合并源数据'!D42/10000 | D22: ='1.承租人-合并源数据'!E42/10000 | E22: ='1.承租人-合并源数据'!F42/10000 | F22: ='1.承租人-合并源数据'!G42/10000 | G22: ='2.承租人-本部源数据'!D42/10000 | H22: ='2.承租人-本部源数据'!E42/10000 | I22: ='2.承租人-本部源数据'!F42/10000 | J22: ='2.承租人-本部源数据'!G42/10000
A23: 负债 | B23: 总负债 | C23: ='1.承租人-合并源数据'!D75/10000 | D23: ='1.承租人-合并源数据'!E75/10000 | E23: ='1.承租人-合并源数据'!F75/10000 | F23: ='1.承租人-合并源数据'!G75/10000 | G23: ='2.承租人-本部源数据'!D75/10000 | H23: ='2.承租人-本部源数据'!E75/10000 | I23: ='2.承租人-本部源数据'!F75/10000 | J23: ='2.承租人-本部源数据'!G75/10000
B24: 流动负债 | C24: ='1.承租人-合并源数据'!D44/10000 | D24: ='1.承租人-合并源数据'!E44/10000 | E24: ='1.承租人-合并源数据'!F44/10000 | F24: ='1.承租人-合并源数据'!G44/10000 | G24: ='2.承租人-本部源数据'!D44/10000 | H24: ='2.承租人-本部源数据'!E44/10000 | I24: ='2.承租人-本部源数据'!F44/10000 | J24: ='2.承租人-本部源数据'!G44/10000
B25: 短期借款 | C25: ='1.承租人-合并源数据'!D45/10000 | D25: ='1.承租人-合并源数据'!E45/10000 | E25: ='1.承租人-合并源数据'!F45/10000 | F25: ='1.承租人-合并源数据'!G45/10000 | G25: ='2.承租人-本部源数据'!D45/10000 | H25: ='2.承租人-本部源数据'!E45/10000 | I25: ='2.承租人-本部源数据'!F45/10000 | J25: ='2.承租人-本部源数据'!G45/10000
B26: 应付账款 | C26: ='1.承租人-合并源数据'!D51/10000 | D26: ='1.承租人-合并源数据'!E51/10000 | E26: ='1.承租人-合并源数据'!F51/10000 | F26: ='1.承租人-合并源数据'!G51/10000 | G26: ='2.承租人-本部源数据'!D51/10000 | H26: ='2.承租人-本部源数据'!E51/10000 | I26: ='2.承租人-本部源数据'!F51/10000 | J26: ='2.承租人-本部源数据'!G51/10000
B27: 预收账款 | C27: ='1.承租人-合并源数据'!D52/10000 | D27: ='1.承租人-合并源数据'!E52/10000 | E27: ='1.承租人-合并源数据'!F52/10000 | F27: ='1.承租人-合并源数据'!G52/10000 | G27: ='2.承租人-本部源数据'!D52/10000 | H27: ='2.承租人-本部源数据'!E52/10000 | I27: ='2.承租人-本部源数据'!F52/10000 | J27: ='2.承租人-本部源数据'!G52/10000
B28: 应付职工薪酬 | C28: ='1.承租人-合并源数据'!D55/10000 | D28: ='1.承租人-合并源数据'!E55/10000 | E28: ='1.承租人-合并源数据'!F55/10000 | F28: ='1.承租人-合并源数据'!G55/10000 | G28: ='2.承租人-本部源数据'!D55/10000 | H28: ='2.承租人-本部源数据'!E55/10000 | I28: ='2.承租人-本部源数据'!F55/10000 | J28: ='2.承租人-本部源数据'!G55/10000
B29: 应交税费 | C29: ='1.承租人-合并源数据'!D56/10000 | D29: ='1.承租人-合并源数据'!E56/10000 | E29: ='1.承租人-合并源数据'!F56/10000 | F29: ='1.承租人-合并源数据'!G56/10000 | G29: ='2.承租人-本部源数据'!D56/10000 | H29: ='2.承租人-本部源数据'!E56/10000 | I29: ='2.承租人-本部源数据'!F56/10000 | J29: ='2.承租人-本部源数据'!G56/10000
B30: 其他应付款 | C30: ='1.承租人-合并源数据'!D57/10000 | D30: ='1.承租人-合并源数据'!E57/10000 | E30: ='1.承租人-合并源数据'!F57/10000 | F30: ='1.承租人-合并源数据'!G57/10000 | G30: ='2.承租人-本部源数据'!D57/10000 | H30: ='2.承租人-本部源数据'!E57/10000 | I30: ='2.承租人-本部源数据'!F57/10000 | J30: ='2.承租人-本部源数据'!G57/10000
B31: 一年内的到期的非流动负债 | C31: ='1.承租人-合并源数据'!D61/10000 | D31: ='1.承租人-合并源数据'!E61/10000 | E31: ='1.承租人-合并源数据'!F61/10000 | F31: ='1.承租人-合并源数据'!G61/10000 | G31: ='2.承租人-本部源数据'!D61/10000 | H31: ='2.承租人-本部源数据'!E61/10000 | I31: ='2.承租人-本部源数据'!F61/10000 | J31: ='2.承租人-本部源数据'!G61/10000
B32: 长期借款 | C32: ='1.承租人-合并源数据'!D64/10000 | D32: ='1.承租人-合并源数据'!E64/10000 | E32: ='1.承租人-合并源数据'!F64/10000 | F32: ='1.承租人-合并源数据'!G64/10000 | G32: ='2.承租人-本部源数据'!D64/10000 | H32: ='2.承租人-本部源数据'!E64/10000 | I32: ='2.承租人-本部源数据'!F64/10000 | J32: ='2.承租人-本部源数据'!G64/10000
B33: 长期应付款 | C33: ='1.承租人-合并源数据'!D69/10000 | D33: ='1.承租人-合并源数据'!E69/10000 | E33: ='1.承租人-合并源数据'!F69/10000 | F33: ='1.承租人-合并源数据'!G69/10000 | G33: ='2.承租人-本部源数据'!D69/10000 | H33: ='2.承租人-本部源数据'!E69/10000 | I33: ='2.承租人-本部源数据'!F69/10000 | J33: ='2.承租人-本部源数据'!G69/10000
B34: 应付债券 | C34: ='1.承租人-合并源数据'!D65/10000 | D34: ='1.承租人-合并源数据'!E65/10000 | E34: ='1.承租人-合并源数据'!F65/10000 | F34: ='1.承租人-合并源数据'!G65/10000 | G34: ='2.承租人-本部源数据'!D65/10000 | H34: ='2.承租人-本部源数据'!E65/10000 | I34: ='2.承租人-本部源数据'!F65/10000 | J34: ='2.承租人-本部源数据'!G65/10000
A35: 权益 | B35: 净资产 | C35: ='1.承租人-合并源数据'!D76/10000 | D35: ='1.承租人-合并源数据'!E76/10000 | E35: ='1.承租人-合并源数据'!F76/10000 | F35: ='1.承租人-合并源数据'!G76/10000 | G35: ='2.承租人-本部源数据'!D76/10000 | H35: ='2.承租人-本部源数据'!E76/10000 | I35: ='2.承租人-本部源数据'!F76/10000 | J35: ='2.承租人-本部源数据'!G76/10000
B36: 实收资本 | C36: ='1.承租人-合并源数据'!D77/10000 | D36: ='1.承租人-合并源数据'!E77/10000 | E36: ='1.承租人-合并源数据'!F77/10000 | F36: ='1.承租人-合并源数据'!G77/10000 | G36: ='2.承租人-本部源数据'!D77/10000 | H36: ='2.承租人-本部源数据'!E77/10000 | I36: ='2.承租人-本部源数据'!F77/10000 | J36: ='2.承租人-本部源数据'!G77/10000
B37: 资本公积 | C37: ='1.承租人-合并源数据'!D81/10000 | D37: ='1.承租人-合并源数据'!E81/10000 | E37: ='1.承租人-合并源数据'!F81/10000 | F37: ='1.承租人-合并源数据'!G81/10000 | G37: ='2.承租人-本部源数据'!D81/10000 | H37: ='2.承租人-本部源数据'!E81/10000 | I37: ='2.承租人-本部源数据'!F81/10000 | J37: ='2.承租人-本部源数据'!G81/10000
B38: 盈余公积 | C38: ='1.承租人-合并源数据'!D85/10000 | D38: ='1.承租人-合并源数据'!E85/10000 | E38: ='1.承租人-合并源数据'!F85/10000 | F38: ='1.承租人-合并源数据'!G85/10000 | G38: ='2.承租人-本部源数据'!D85/10000 | H38: ='2.承租人-本部源数据'!E85/10000 | I38: ='2.承租人-本部源数据'!F85/10000 | J38: ='2.承租人-本部源数据'!G85/10000
B39: 未分配利润 | C39: ='1.承租人-合并源数据'!D87/10000 | D39: ='1.承租人-合并源数据'!E87/10000 | E39: ='1.承租人-合并源数据'!F87/10000 | F39: ='1.承租人-合并源数据'!G87/10000 | G39: ='2.承租人-本部源数据'!D87/10000 | H39: ='2.承租人-本部源数据'!E87/10000 | I39: ='2.承租人-本部源数据'!F87/10000 | J39: ='2.承租人-本部源数据'!G87/10000
A40: 盈利能力 | B40: 营业收入 | C40: ='1.承租人-合并源数据'!D94/10000 | D40: ='1.承租人-合并源数据'!E94/10000 | E40: ='1.承租人-合并源数据'!F94/10000 | F40: ='1.承租人-合并源数据'!G94/10000 | G40: ='2.承租人-本部源数据'!D94/10000 | H40: ='2.承租人-本部源数据'!E94/10000 | I40: ='2.承租人-本部源数据'!F94/10000 | J40: ='2.承租人-本部源数据'!G94/10000
...

Sheet 4.担保人-合并源数据
A1: 序号 | B1: 报表分类 | C1: 标准会计科目 | D1: 2022年 | E1: 2023年 | F1: 2024年 | G1: 最新一期
A2: 1 | B2: 资产负债表 | C2: 流动资产合计 | D2: =SUM(D3,D5,D6,D7,D8,D9,D10,D11,D12,D13,D14,D15,D16,D17,D18,D19,D20,D21,D22) | E2: =SUM(E3,E5,E6,E7,E8,E9,E10,E11,E12,E13,E14,E15,E16,E17,E18,E19,E20,E21,E22) | F2: =SUM(F3,F5,F6,F7,F8,F9,F10,F11,F12,F13,F14,F15,F16,F17,F18,F19,F20,F21,F22) | G2: =SUM(G3,G5,G6,G7,G8,G9,G10,G11,G12,G13,G14,G15,G16,G17,G18,G19,G20,G21,G22)
A3: 2 | C3: 货币资金
A4: 3 | C4: 其中：受限货币资金
A5: 4 | C5: 结算备付金
A6: 5 | C6: 拆出资金
A7: 6 | C7: 交易性金融资产 / 短期投资
A8: 7 | C8: 衍生金融资产
A9: 8 | C9: 应收票据
A10: 9 | C10: 应收账款
A11: 10 | C11: 应收款项融资
A12: 11 | C12: 预付款项
A13: 12 | C13: 应收保费 / 应收分保账款
A14: 13 | C14: 应收利息
... A22: 21 | C22: 其他流动资产
A23: 22 | C23: 非流动资产合计 | D23: =SUM(D24,D25,D26,D27,D28,D29,D30,D31,D32,D34,D35,D36,D37,D38,D39,D40,D41,D42) | E23: =SUM(E24,E25,E26,E27,E28,E29,E30,E31,E32,E34,E35,E36,E37,E38,E39,E40,E41,E42) | F23: =SUM(F24,F25,F26,F27,F28,F29,F30,F31,F32,F34,F35,F36,F37,F38,F39,F40,F41,F42) | G23: =SUM(G24,G25,G26,G27,G28,G29,G30,G31,G32,G34,G35,G36,G37,G38,G39,G40,G41,G42)
A24: 23 | C24: 发放贷款和垫款
A25: 24 | C25: 债权投资 / 持有至到期投资
A26: 25 | C26: 其他债权投资 / 可供出售金融资产
A27: 26 | C27: 长期应收款
A28: 27 | C28: 长期股权投资
A29: 28 | C29: 其他权益工具投资
A30: 29 | C30: 其他非流动金融资产
A31: 30 | C31: 投资性房地产
A32: 31 | C32: 固定资产
A33: 32 | C33: 其中：固定资产清理
A34: 33 | C34: 在建工程
A35: 34 | C35: 生产性生物资产 / 油气资产
... A42: 41 | C42: 其他非流动资产
A43: 42 | C43: 资产总计 | D43: =D2+D23 | E43: =E2+E23 | F43: =F2+F23 | G43: =G2+G23
A44: 43 | C44: 流动负债合计 | D44: =SUM(D45,D46,D47,D48,D49,D50,D51,D52,D53,D54,D55,D56,D57,D60,D61,D62) | E44: =SUM(E45,E46,E47,E48,E49,E50,E51,E52,E53,E54,E55,E56,E57,E60,E61,E62) | F44: =SUM(F45,F46,F47,F48,F49,F50,F51,F52,F53,F54,F55,F56,F57,F60,F61,F62) | G44: =SUM(G45,G46,G47,G48,G49,G50,G51,G52,G53,G54,G55,G56,G57,G60,G61,G62)
A45: 44 | C45: 短期借款
A46: 45 | C46: 向中央银行借款
A47: 46 | C47: 拆入资金 / 吸收存款及同业存放
A48: 47 | C48: 交易性金融负债
A49: 48 | C49: 衍生金融负债
A50: 49 | C50: 应付票据
A51: 50 | C51: 应付账款
A52: 51 | C52: 预收款项
A53: 52 | C53: 合同负债
...

Sheet 5.担保人-本部源数据
A1: 序号 | B1: 报表分类 | C1: 标准会计科目 | D1: 2022年 | E1: 2023年 | F1: 2024年 | G1: 最新一期
A2: 1 | B2: 资产负债表 | C2: 流动资产合计 | D2: =SUM(D3,D5,D6,D7,D8,D9,D10,D11,D12,D13,D14,D15,D16,D17,D18,D19,D20,D21,D22) | E2: =SUM(E3,E5,E6,E7,E8,E9,E10,E11,E12,E13,E14,E15,E16,E17,E18,E19,E20,E21,E22) | F2: =SUM(F3,F5,F6,F7,F8,F9,F10,F11,F12,F13,F14,F15,F16,F17,F18,F19,F20,F21,F22) | G2: =SUM(G3,G5,G6,G7,G8,G9,G10,G11,G12,G13,G14,G15,G16,G17,G18,G19,G20,G21,G22)
A3: 2 | C3: 货币资金
A4: 3 | C4: 其中：受限货币资金
A5: 4 | C5: 结算备付金
A6: 5 | C6: 拆出资金
A7: 6 | C7: 交易性金融资产 / 短期投资
A8: 7 | C8: 衍生金融资产
A9: 8 | C9: 应收票据
A10: 9 | C10: 应收账款
A11: 10 | C11: 应收款项融资
A12: 11 | C12: 预付款项
A13: 12 | C13: 应收保费 / 应收分保账款
A14: 13 | C14: 应收利息
... A22: 21 | C22: 其他流动资产
A23: 22 | C23: 非流动资产合计 | D23: =SUM(D24,D25,D26,D27,D28,D29,D30,D31,D32,D34,D35,D36,D37,D38,D39,D40,D41,D42) | E23: =SUM(E24,E25,E26,E27,E28,E29,E30,E31,E32,E34,E35,E36,E37,E38,E39,E40,E41,E42) | F23: =SUM(F24,F25,F26,F27,F28,F29,F30,F31,F32,F34,F35,F36,F37,F38,F39,F40,F41,F42) | G23: =SUM(G24,G25,G26,G27,G28,G29,G30,G31,G32,G34,G35,G36,G37,G38,G39,G40,G41,G42)
A24: 23 | C24: 发放贷款和垫款
A25: 24 | C25: 债权投资 / 持有至到期投资
A26: 25 | C26: 其他债权投资 / 可供出售金融资产
A27: 26 | C27: 长期应收款
A28: 27 | C28: 长期股权投资
A29: 28 | C29: 其他权益工具投资
A30: 29 | C30: 其他非流动金融资产
A31: 30 | C31: 投资性房地产
A32: 31 | C32: 固定资产
A33: 32 | C33: 其中：固定资产清理
A34: 33 | C34: 在建工程
A35: 34 | C35: 生产性生物资产 / 油气资产
... A42: 41 | C42: 其他非流动资产
A43: 42 | C43: 资产总计 | D43: =D2+D23 | E43: =E2+E23 | F43: =F2+F23 | G43: =G2+G23
A44: 43 | C44: 流动负债合计 | D44: =SUM(D45,D46,D47,D48,D49,D50,D51,D52,D53,D54,D55,D56,D57,D60,D61,D62) | E44: =SUM(E45,E46,E47,E48,E49,E50,E51,E52,E53,E54,E55,E56,E57,E60,E61,E62) | F44: =SUM(F45,F46,F47,F48,F49,F50,F51,F52,F53,F54,F55,F56,F57,F60,F61,F62) | G44: =SUM(G45,G46,G47,G48,G49,G50,G51,G52,G53,G54,G55,G56,G57,G60,G61,G62)
A45: 44 | C45: 短期借款
A46: 45 | C46: 向中央银行借款
A47: 46 | C47: 拆入资金 / 吸收存款及同业存放
A48: 47 | C48: 交易性金融负债
A49: 48 | C49: 衍生金融负债
A50: 49 | C50: 应付票据
A51: 50 | C51: 应付账款
A52: 51 | C52: 预收款项
A53: 52 | C53: 合同负债
...

Sheet 6.担保人-财务分析
A1: 分析板块 | B1: 财务分析科目 | C1: 合并口径 (单位:万元) | G1: 本部口径 (单位:万元)
C2: 2022年 | D2: 2023年 | E2: 2024年 | F2: 最新一期 | G2: 2022年 | H2: 2023年 | I2: 2024年 | J2: 最新一期
A3: 资产 | B3: 总资产 | C3: ='4.担保人-合并源数据'!D43/10000 | D3: ='4.担保人-合并源数据'!E43/10000 | E3: ='4.担保人-合并源数据'!F43/10000 | F3: ='4.担保人-合并源数据'!G43/10000 | G3: ='5.担保人-本部源数据'!D43/10000 | H3: ='5.担保人-本部源数据'!E43/10000 | I3: ='5.担保人-本部源数据'!F43/10000 | J3: ='5.担保人-本部源数据'!G43/10000
B4: 流动资产 | C4: ='4.担保人-合并源数据'!D2/10000 | D4: ='4.担保人-合并源数据'!E2/10000 | E4: ='4.担保人-合并源数据'!F2/10000 | F4: ='4.担保人-合并源数据'!G2/10000 | G4: ='5.担保人-本部源数据'!D2/10000 | H4: ='5.担保人-本部源数据'!E2/10000 | I4: ='5.担保人-本部源数据'!F2/10000 | J4: ='5.担保人-本部源数据'!G2/10000
B5: 货币资金 | C5: ='4.担保人-合并源数据'!D3/10000 | D5: ='4.担保人-合并源数据'!E3/10000 | E5: ='4.担保人-合并源数据'!F3/10000 | F5: ='4.担保人-合并源数据'!G3/10000 | G5: ='5.担保人-本部源数据'!D3/10000 | H5: ='5.担保人-本部源数据'!E3/10000 | I5: ='5.担保人-本部源数据'!F3/10000 | J5: ='5.担保人-本部源数据'!G3/10000
B6: 应收帐款 | C6: ='4.担保人-合并源数据'!D10/10000 | D6: ='4.担保人-合并源数据'!E10/10000 | E6: ='4.担保人-合并源数据'!F10/10000 | F6: ='4.担保人-合并源数据'!G10/10000 | G6: ='5.担保人-本部源数据'!D10/10000 | H6: ='5.担保人-本部源数据'!E10/10000 | I6: ='5.担保人-本部源数据'!F10/10000 | J6: ='5.担保人-本部源数据'!G10/10000
B7: 其他应收款 | C7: ='4.担保人-合并源数据'!D16/10000 | D7: ='4.担保人-合并源数据'!E16/10000 | E7: ='4.担保人-合并源数据'!F16/10000 | F7: ='4.担保人-合并源数据'!G16/10000 | G7: ='5.担保人-本部源数据'!D16/10000 | H7: ='5.担保人-本部源数据'!E16/10000 | I7: ='5.担保人-本部源数据'!F16/10000 | J7: ='5.担保人-本部源数据'!G16/10000
B8: 预付帐款 | C8: ='4.担保人-合并源数据'!D12/10000 | D8: ='4.担保人-合并源数据'!E12/10000 | E8: ='4.担保人-合并源数据'!F12/10000 | F8: ='4.担保人-合并源数据'!G12/10000 | G8: ='5.担保人-本部源数据'!D12/10000 | H8: ='5.担保人-本部源数据'!E12/10000 | I8: ='5.担保人-本部源数据'!F12/10000 | J8: ='5.担保人-本部源数据'!G12/10000
B9: 存货 | C9: ='4.担保人-合并源数据'!D18/10000 | D9: ='4.担保人-合并源数据'!E18/10000 | E9: ='4.担保人-合并源数据'!F18/10000 | F9: ='4.担保人-合并源数据'!G18/10000 | G9: ='5.担保人-本部源数据'!D18/10000 | H9: ='5.担保人-本部源数据'!E18/10000 | I9: ='5.担保人-本部源数据'!F18/10000 | J9: ='5.担保人-本部源数据'!G18/10000
B10: 其他流动资产 | C10: ='4.担保人-合并源数据'!D22/10000 | D10: ='4.担保人-合并源数据'!E22/10000 | E10: ='4.担保人-合并源数据'!F22/10000 | F10: ='4.担保人-合并源数据'!G22/10000 | G10: ='5.担保人-本部源数据'!D22/10000 | H10: ='5.担保人-本部源数据'!E22/10000 | I10: ='5.担保人-本部源数据'!F22/10000 | J10: ='5.担保人-本部源数据'!G22/10000
B11: 持有至到期投资 | C11: ='4.担保人-合并源数据'!D25/10000 | D11: ='4.担保人-合并源数据'!E25/10000 | E11: ='4.担保人-合并源数据'!F25/10000 | F11: ='4.担保人-合并源数据'!G25/10000 | G11: ='5.担保人-本部源数据'!D25/10000 | H11: ='5.担保人-本部源数据'!E25/10000 | I11: ='5.担保人-本部源数据'!F25/10000 | J11: ='5.担保人-本部源数据'!G25/10000
B12: 长期股权投资 | C12: ='4.担保人-合并源数据'!D28/10000 | D12: ='4.担保人-合并源数据'!E28/10000 | E12: ='4.担保人-合并源数据'!F28/10000 | F12: ='4.担保人-合并源数据'!G28/10000 | G12: ='5.担保人-本部源数据'!D28/10000 | H12: ='5.担保人-本部源数据'!E28/10000 | I12: ='5.担保人-本部源数据'!F28/10000 | J12: ='5.担保人-本部源数据'!G28/10000
B13: 投资性房地产 | C13: ='4.担保人-合并源数据'!D31/10000 | D13: ='4.担保人-合并源数据'!E31/10000 | E13: ='4.担保人-合并源数据'!F31/10000 | F13: ='4.担保人-合并源数据'!G31/10000 | G13: ='5.担保人-本部源数据'!D31/10000 | H13: ='5.担保人-本部源数据'!E31/10000 | I13: ='5.担保人-本部源数据'!F31/10000 | J13: ='5.担保人-本部源数据'!G31/10000
B14: 固定资产 | C14: ='4.担保人-合并源数据'!D32/10000 | D14: ='4.担保人-合并源数据'!E32/10000 | E14: ='4.担保人-合并源数据'!F32/10000 | F14: ='4.担保人-合并源数据'!G32/10000 | G14: ='5.担保人-本部源数据'!D32/10000 | H14: ='5.担保人-本部源数据'!E32/10000 | I14: ='5.担保人-本部源数据'!F32/10000 | J14: ='5.担保人-本部源数据'!G32/10000
B15: 其中：本期新增折旧
B16: 在建工程 | C16: ='4.担保人-合并源数据'!D34/10000 | D16: ='4.担保人-合并源数据'!E34/10000 | E16: ='4.担保人-合并源数据'!F34/10000 | F16: ='4.担保人-合并源数据'!G34/10000 | G16: ='5.担保人-本部源数据'!D34/10000 | H16: ='5.担保人-本部源数据'!E34/10000 | I16: ='5.担保人-本部源数据'!F34/10000 | J16: ='5.担保人-本部源数据'!G34/10000
B17: 无形资产 | C17: ='4.担保人-合并源数据'!D37/10000 | D17: ='4.担保人-合并源数据'!E37/10000 | E17: ='4.担保人-合并源数据'!F37/10000 | F17: ='4.担保人-合并源数据'!G37/10000 | G17: ='5.担保人-本部源数据'!D37/10000 | H17: ='5.担保人-本部源数据'!E37/10000 | I17: ='5.担保人-本部源数据'!F37/10000 | J17: ='5.担保人-本部源数据'!G37/10000
B18: 其中：本期新增摊销
B19: 长期待摊费用 | C19: ='4.担保人-合并源数据'!D40/10000 | D19: ='4.担保人-合并源数据'!E40/10000 | E19: ='4.担保人-合并源数据'!F40/10000 | F19: ='4.担保人-合并源数据'!G40/10000 | G19: ='5.担保人-本部源数据'!D40/10000 | H19: ='5.担保人-本部源数据'!E40/10000 | I19: ='5.担保人-本部源数据'!F40/10000 | J19: ='5.担保人-本部源数据'!G40/10000
B20: 其中：本期新增摊销(长待)
B21: 递延所得税资产 | C21: ='4.担保人-合并源数据'!D41/10000 | D21: ='4.担保人-合并源数据'!E41/10000 | E21: ='4.担保人-合并源数据'!F41/10000 | F21: ='4.担保人-合并源数据'!G41/10000 | G21: ='5.担保人-本部源数据'!D41/10000 | H21: ='5.担保人-本部源数据'!E41/10000 | I21: ='5.担保人-本部源数据'!F41/10000 | J21: ='5.担保人-本部源数据'!G41/10000
B22: 其他非流动资产 | C22: ='4.担保人-合并源数据'!D42/10000 | D22: ='4.担保人-合并源数据'!E42/10000 | E22: ='4.担保人-合并源数据'!F42/10000 | F22: ='4.担保人-合并源数据'!G42/10000 | G22: ='5.担保人-本部源数据'!D42/10000 | H22: ='5.担保人-本部源数据'!E42/10000 | I22: ='5.担保人-本部源数据'!F42/10000 | J22: ='5.担保人-本部源数据'!G42/10000
A23: 负债 | B23: 总负债 | C23: ='4.担保人-合并源数据'!D75/10000 | D23: ='4.担保人-合并源数据'!E75/10000 | E23: ='4.担保人-合并源数据'!F75/10000 | F23: ='4.担保人-合并源数据'!G75/10000 | G23: ='5.担保人-本部源数据'!D75/10000 | H23: ='5.担保人-本部源数据'!E75/10000 | I23: ='5.担保人-本部源数据'!F75/10000 | J23: ='5.担保人-本部源数据'!G75/10000
B24: 流动负债 | C24: ='4.担保人-合并源数据'!D44/10000 | D24: ='4.担保人-合并源数据'!E44/10000 | E24: ='4.担保人-合并源数据'!F44/10000 | F24: ='4.担保人-合并源数据'!G44/10000 | G24: ='5.担保人-本部源数据'!D44/10000 | H24: ='5.担保人-本部源数据'!E44/10000 | I24: ='5.担保人-本部源数据'!F44/10000 | J24: ='5.担保人-本部源数据'!G44/10000
B25: 短期借款 | C25: ='4.担保人-合并源数据'!D45/10000 | D25: ='4.担保人-合并源数据'!E45/10000 | E25: ='4.担保人-合并源数据'!F45/10000 | F25: ='4.担保人-合并源数据'!G45/10000 | G25: ='5.担保人-本部源数据'!D45/10000 | H25: ='5.担保人-本部源数据'!E45/10000 | I25: ='5.担保人-本部源数据'!F45/10000 | J25: ='5.担保人-本部源数据'!G45/10000
B26: 应付账款 | C26: ='4.担保人-合并源数据'!D51/10000 | D26: ='4.担保人-合并源数据'!E51/10000 | E26: ='4.担保人-合并源数据'!F51/10000 | F26: ='4.担保人-合并源数据'!G51/10000 | G26: ='5.担保人-本部源数据'!D51/10000 | H26: ='5.担保人-本部源数据'!E51/10000 | I26: ='5.担保人-本部源数据'!F51/10000 | J26: ='5.担保人-本部源数据'!G51/10000
B27: 预收账款 | C27: ='4.担保人-合并源数据'!D52/10000 | D27: ='4.担保人-合并源数据'!E52/10000 | E27: ='4.担保人-合并源数据'!F52/10000 | F27: ='4.担保人-合并源数据'!G52/10000 | G27: ='5.担保人-本部源数据'!D52/10000 | H27: ='5.担保人-本部源数据'!E52/10000 | I27: ='5.担保人-本部源数据'!F52/10000 | J27: ='5.担保人-本部源数据'!G52/10000
B28: 应付职工薪酬 | C28: ='4.担保人-合并源数据'!D55/10000 | D28: ='4.担保人-合并源数据'!E55/10000 | E28: ='4.担保人-合并源数据'!F55/10000 | F28: ='4.担保人-合并源数据'!G55/10000 | G28: ='5.担保人-本部源数据'!D55/10000 | H28: ='5.担保人-本部源数据'!E55/10000 | I28: ='5.担保人-本部源数据'!F55/10000 | J28: ='5.担保人-本部源数据'!G55/10000
B29: 应交税费 | C29: ='4.担保人-合并源数据'!D56/10000 | D29: ='4.担保人-合并源数据'!E56/10000 | E29: ='4.担保人-合并源数据'!F56/10000 | F29: ='4.担保人-合并源数据'!G56/10000 | G29: ='5.担保人-本部源数据'!D56/10000 | H29: ='5.担保人-本部源数据'!E56/10000 | I29: ='5.担保人-本部源数据'!F56/10000 | J29: ='5.担保人-本部源数据'!G56/10000
B30: 其他应付款 | C30: ='4.担保人-合并源数据'!D57/10000 | D30: ='4.担保人-合并源数据'!E57/10000 | E30: ='4.担保人-合并源数据'!F57/10000 | F30: ='4.担保人-合并源数据'!G57/10000 | G30: ='5.担保人-本部源数据'!D57/10000 | H30: ='5.担保人-本部源数据'!E57/10000 | I30: ='5.担保人-本部源数据'!F57/10000 | J30: ='5.担保人-本部源数据'!G57/10000
B31: 一年内的到期的非流动负债 | C31: ='4.担保人-合并源数据'!D61/10000 | D31: ='4.担保人-合并源数据'!E61/10000 | E31: ='4.担保人-合并源数据'!F61/10000 | F31: ='4.担保人-合并源数据'!G61/10000 | G31: ='5.担保人-本部源数据'!D61/10000 | H31: ='5.担保人-本部源数据'!E61/10000 | I31: ='5.担保人-本部源数据'!F61/10000 | J31: ='5.担保人-本部源数据'!G61/10000
B32: 长期借款 | C32: ='4.担保人-合并源数据'!D64/10000 | D32: ='4.担保人-合并源数据'!E64/10000 | E32: ='4.担保人-合并源数据'!F64/10000 | F32: ='4.担保人-合并源数据'!G64/10000 | G32: ='5.担保人-本部源数据'!D64/10000 | H32: ='5.担保人-本部源数据'!E64/10000 | I32: ='5.担保人-本部源数据'!F64/10000 | J32: ='5.担保人-本部源数据'!G64/10000
B33: 长期应付款 | C33: ='4.担保人-合并源数据'!D69/10000 | D33: ='4.担保人-合并源数据'!E69/10000 | E33: ='4.担保人-合并源数据'!F69/10000 | F33: ='4.担保人-合并源数据'!G69/10000 | G33: ='5.担保人-本部源数据'!D69/10000 | H33: ='5.担保人-本部源数据'!E69/10000 | I33: ='5.担保人-本部源数据'!F69/10000 | J33: ='5.担保人-本部源数据'!G69/10000
B34: 应付债券 | C34: ='4.担保人-合并源数据'!D65/10000 | D34: ='4.担保人-合并源数据'!E65/10000 | E34: ='4.担保人-合并源数据'!F65/10000 | F34: ='4.担保人-合并源数据'!G65/10000 | G34: ='5.担保人-本部源数据'!D65/10000 | H34: ='5.担保人-本部源数据'!E65/10000 | I34: ='5.担保人-本部源数据'!F65/10000 | J34: ='5.担保人-本部源数据'!G65/10000
A35: 权益 | B35: 净资产 | C35: ='4.担保人-合并源数据'!D76/10000 | D35: ='4.担保人-合并源数据'!E76/10000 | E35: ='4.担保人-合并源数据'!F76/10000 | F35: ='4.担保人-合并源数据'!G76/10000 | G35: ='5.担保人-本部源数据'!D76/10000 | H35: ='5.担保人-本部源数据'!E76/10000 | I35: ='5.担保人-本部源数据'!F76/10000 | J35: ='5.担保人-本部源数据'!G76/10000
B36: 实收资本 | C36: ='4.担保人-合并源数据'!D77/10000 | D36: ='4.担保人-合并源数据'!E77/10000 | E36: ='4.担保人-合并源数据'!F77/10000 | F36: ='4.担保人-合并源数据'!G77/10000 | G36: ='5.担保人-本部源数据'!D77/10000 | H36: ='5.担保人-本部源数据'!E77/10000 | I36: ='5.担保人-本部源数据'!F77/10000 | J36: ='5.担保人-本部源数据'!G77/10000
B37: 资本公积 | C37: ='4.担保人-合并源数据'!D81/10000 | D37: ='4.担保人-合并源数据'!E81/10000 | E37: ='4.担保人-合并源数据'!F81/10000 | F37: ='4.担保人-合并源数据'!G81/10000 | G37: ='5.担保人-本部源数据'!D81/10000 | H37: ='5.担保人-本部源数据'!E81/10000 | I37: ='5.担保人-本部源数据'!F81/10000 | J37: ='5.担保人-本部源数据'!G81/10000
B38: 盈余公积 | C38: ='4.担保人-合并源数据'!D85/10000 | D38: ='4.担保人-合并源数据'!E85/10000 | E38: ='4.担保人-合并源数据'!F85/10000 | F38: ='4.担保人-合并源数据'!G85/10000 | G38: ='5.担保人-本部源数据'!D85/10000 | H38: ='5.担保人-本部源数据'!E85/10000 | I38: ='5.担保人-本部源数据'!F85/10000 | J38: ='5.担保人-本部源数据'!G85/10000
B39: 未分配利润 | C39: ='4.担保人-合并源数据'!D87/10000 | D39: ='4.担保人-合并源数据'!E87/10000 | E39: ='4.担保人-合并源数据'!F87/10000 | F39: ='4.担保人-合并源数据'!G87/10000 | G39: ='5.担保人-本部源数据'!D87/10000 | H39: ='5.担保人-本部源数据'!E87/10000 | I39: ='5.担保人-本部源数据'!F87/10000 | J39: ='5.担保人-本部源数据'!G87/10000
A40: 盈利能力 | B40: 营业收入 | C40: ='4.担保人-合并源数据'!D94/10000 | D40: ='4.担保人-合并源数据'!E94/10000 | E40: ='4.担保人-合并源数据'!F94/10000 | F40: ='4.担保人-合并源数据'!G94/10000 | G40: ='5.担保人-本部源数据'!D94/10000 | H40: ='5.担保人-本部源数据'!E94/10000 | I40: ='5.担保人-本部源数据'!F94/10000 | J40: ='5.担保人-本部源数据'!G94/10000
...
